<mujocoinclude>
  <body name="base_link" quat="0 0 0 1" childclass="rm65">
    <site name="armbase" quat="0 0 0 1"/>
    <inertial pos="-0.00043263 -3.2791E-05 0.059984" quat="1.0 0.0 0.0 0.0" mass="0.84048" diaginertia="0.001724 0.0017077 0.00090401" />
    <geom name="base_link_collision" pos="0 0 0" quat="1.0 0.0 0.0 0.0" type="mesh" mesh="base_link.STL" class="collision" />
    <geom pos="0 0 0" quat="1.0 0.0 0.0 0.0" type="mesh" class="visual" name="base_link_visual_0" mesh="base_link_0" material="base_link_Material-外壳_001-material" />
    <geom pos="0 0 0" quat="1.0 0.0 0.0 0.0" type="mesh" class="visual" name="base_link_visual_1" mesh="base_link_1" material="base_link_Material-塑胶_001-material" />
    <geom pos="0 0 0" quat="1.0 0.0 0.0 0.0" type="mesh" class="visual" name="base_link_visual_2" mesh="base_link_2" material="base_link_Material-橡胶_001-material" />
    <body name="link1" pos="0 0 0.2405" quat="1.0 0.0 0.0 0.0">
      <inertial pos="1.4674E-07 0.021109 -0.025186" quat="1.0 0.0 0.0 0.0" mass="0.59356" diaginertia="0.0012661 0.0011817 0.00056135" />
      <joint name="joint1" type="hinge" class="upper_limb" range="-3.106 3.106" axis="0 0 -1" />
      <geom name="link1_collision" pos="0 0 0" quat="1.0 0.0 0.0 0.0" type="mesh" mesh="link1.STL" class="collision" />
      <geom pos="0 0 0" quat="1.0 0.0 0.0 0.0" type="mesh" class="visual" name="link1_visual_0" mesh="link1_0" material="base_link_Material-外壳_001-material" />
      <geom pos="0 0 0" quat="1.0 0.0 0.0 0.0" type="mesh" class="visual" name="link1_visual_1" mesh="link1_1" material="base_link_Material-橡胶_001-material" />
      <body name="link2" pos="0 0 0" quat="0.4999981633974483 0.49999999999662686 -0.49999999999662686 0.5000018366025516">
        <inertial pos="0.15226 4.2499E-07 -0.0062026" quat="1.0 0.0 0.0 0.0" mass="0.86418" diaginertia="0.00063253 0.0020527 0.0019528" />
        <joint name="joint2" type="hinge" class="upper_limb" range="-2.269 2.269" axis="0 0 1" />
        <geom name="link2_collision" pos="0 0 0" quat="1.0 0.0 0.0 0.0" type="mesh" mesh="link2.STL" class="collision" />
        <geom pos="0 0 0" quat="1.0 0.0 0.0 0.0" type="mesh" class="visual" name="link2_visual_0" mesh="link2_0" material="base_link_Material-橡胶_001-material" />
        <geom pos="0 0 0" quat="1.0 0.0 0.0 0.0" type="mesh" class="visual" name="link2_visual_1" mesh="link2_1" material="base_link_Material-外壳_001-material" />
        <body name="link3" pos="0.256 0 0" quat="0.7071054825112363 0.0 0.0 0.7071080798594735">
          <inertial pos="4.8002E-06 -0.059593 0.010569" quat="1.0 0.0 0.0 0.0" mass="0.28965" diaginertia="0.00063737 0.00015649 0.00061418" />
          <joint name="joint3" type="hinge" class="upper_limb" range="-2.356 2.356" axis="0 0 1" />
          <geom name="link3_collision" pos="0 0 0" quat="1.0 0.0 0.0 0.0" type="mesh" mesh="link3.STL" class="collision" />
          <geom pos="0 0 0" quat="1.0 0.0 0.0 0.0" type="mesh" class="visual" name="link3_visual_0" mesh="link3_0" material="base_link_Material-外壳_001-material" />
          <geom pos="0 0 0" quat="1.0 0.0 0.0 0.0" type="mesh" class="visual" name="link3_visual_1" mesh="link3_1" material="base_link_Material-橡胶_001-material" />
          <body name="link4" pos="0 -0.21 0" quat="0.7071054825112363 0.7071080798594735 0.0 0.0">
            <inertial pos="2.1531E-06 -0.018042 -0.021539" quat="1.0 0.0 0.0 0.0" mass="0.23942" diaginertia="0.00028594 0.00026273 0.00011989" />
            <joint name="joint4" type="hinge" class="lower_limb" range="-3.106 3.106" axis="0 0 -1" />
            <geom name="link4_collision" pos="0 0 0" quat="1.0 0.0 0.0 0.0" type="mesh" mesh="link4.STL" class="collision" />
            <geom pos="0 0 0" quat="1.0 0.0 0.0 0.0" type="mesh" class="visual" name="link4_visual_0" mesh="link4_0" material="base_link_Material-外壳_001-material" />
            <geom pos="0 0 0" quat="1.0 0.0 0.0 0.0" type="mesh" class="visual" name="link4_visual_1" mesh="link4_1" material="base_link_Material-橡胶_001-material" />
            <body name="link5" pos="0 0 0" quat="0.7071054825112363 -0.7071080798594735 0.0 0.0">
              <inertial pos="4.5765E-06 -0.059382 0.0073678" quat="1.0 0.0 0.0 0.0" mass="0.21879" diaginertia="0.00035053 0.00010492 0.00033447" />
              <joint name="joint5" type="hinge" class="lower_limb" range="-2.234 2.234" axis="0 0 1" />
              <geom name="link5_collision" pos="0 0 0" quat="1.0 0.0 0.0 0.0" type="mesh" mesh="link5.STL" class="collision" />
              <geom pos="0 0 0" quat="1.0 0.0 0.0 0.0" type="mesh" class="visual" name="link5_visual_0" mesh="link5_0" material="base_link_Material-外壳_001-material" />
              <geom pos="0 0 0" quat="1.0 0.0 0.0 0.0" type="mesh" class="visual" name="link5_visual_1" mesh="link5_1" material="base_link_Material-橡胶_001-material" />
              <body name="link6" pos="0 -0.144 0" quat="0.7071054825112363 0.7071080798594735 0.0 0.0">
                <inertial pos="0.00081643 1.3298E-05 -0.012705" quat="1.0 0.0 0.0 0.0" mass="0.065035" diaginertia="2.1143e-05 1.811e-05 3.19e-05" />
                <joint name="joint6" type="hinge" class="lower_limb" range="-6.28 6.28" axis="0 0 1" />
                <geom name="link6_collision" pos="0 0 0" quat="1.0 0.0 0.0 0.0" type="mesh" mesh="link6.STL" class="collision" />
                <geom pos="0 0 0" quat="1.0 0.0 0.0 0.0" type="mesh" class="visual" name="link6_visual_0" mesh="link6_0" material="base_link_Material-外壳_001-material" />
                <geom pos="0 0 0" quat="1.0 0.0 0.0 0.0" type="mesh" class="visual" name="link6_visual_1" mesh="link6_1" material="base_link_Material-橡胶_001-material" />
                <body name="camera_base_link" pos="0 0 0" quat="-3.673205103346574e-06 -0.0 0.0 0.9999999999932537">
                  <inertial pos="0.04582 -2.3076E-07 -0.005454" quat="1.0 0.0 0.0 0.0" mass="0.051307" diaginertia="1.5914e-05 8.6532e-05 0.00010189" />
                  <geom name="camera_base_link_collision" pos="0 0 0" quat="1.0 0.0 0.0 0.0" type="mesh" mesh="camera_base_link.STL" class="collision" />
                  <geom name="camera_base_link_visual" pos="0 0 0" quat="1.0 0.0 0.0 0.0" type="mesh" mesh="camera_base_link.STL" material="camera_black" class="visual" />
                  <body name="gripper_base_link" pos="0 0 -0.001" quat="1.0 0.0 0.0 0.0">
                    <inertial pos="-6.7908E-06 -3.0546E-06 0.038387" quat="1.0 0.0 0.0 0.0" mass="0.07993" diaginertia="6.2249e-05 5.235e-05 2.2082e-05" />
                    <geom name="gripper_base_link_collision" pos="0 0 0" quat="1.0 0.0 0.0 0.0" type="mesh" mesh="gripper_base_link.STL" class="collision" />
                    <geom name="gripper_base_link_visual" pos="0 0 0" quat="1.0 0.0 0.0 0.0" type="mesh" mesh="gripper_base_link.STL" material="default_material" class="visual" />
                    <site name="endpoint" pos="0 0 0.14" quat="0 0.707 0 0.707"/>
                    <body name="link7" pos="-0.009 0.04 0.083" quat="1.0 0.0 0.0 0.0">
                      <inertial pos="0.009 -0.0087669 0.013992" quat="1.0 0.0 0.0 0.0" mass="0.0024292" diaginertia="5.7398e-07 5.1061e-07 2.6747e-07" />
                      <joint name="gripper_joint1" type="hinge" range="0 0.82" axis="-1 0 0" armature="0.001" damping="0.05"/>
                      <!-- <geom name="link7_collision" pos="0 0 0" quat="1.0 0.0 0.0 0.0" type="mesh" mesh="link7.STL" class="collision" /> -->
                      <geom name="link7_visual" pos="0 0 0" quat="1.0 0.0 0.0 0.0" type="mesh" mesh="link7.STL" material="camera_black" class="visual" />
                      <body name="link11" pos="0 -0.0223 0.035591" quat="1.0 0.0 0.0 0.0">
                        <inertial pos="0.009 -0.011864 0.011367" quat="1.0 0.0 0.0 0.0" mass="0.0045068" diaginertia="5.3203e-07 5.1288e-07 2.009e-07" />
                        <joint name="gripper_joint5" type="hinge" range="0 0.82" axis="1 0 0" />
                        <!-- <geom name="link11_collision" pos="0 0 0" quat="1.0 0.0 0.0 0.0" type="mesh" mesh="link11.STL" class="collision" /> -->
                        <geom name="link11_visual" pos="0 0 0" quat="1.0 0.0 0.0 0.0" type="mesh" mesh="link11.STL" material="camera_black" class="visual" />
                      </body>
                    </body>
                    <body name="link8" pos="-0.009 0.03 0.085" quat="1.0 0.0 0.0 0.0">
                      <inertial pos="0.009 -0.0087435 0.013955" quat="1.0 0.0 0.0 0.0" mass="0.0038971" diaginertia="6.2305e-07 5.6941e-07 3.0871e-07" />
                      <joint name="gripper_joint2" type="hinge" range="0 0.82" axis="-1 0 0" />
                      <!-- <geom name="link8_collision" pos="0 0 0" quat="1.0 0.0 0.0 0.0" type="mesh" mesh="link8.STL" class="collision" /> -->
                      <geom name="link8_visual" pos="0 0 0" quat="1.0 0.0 0.0 0.0" type="mesh" mesh="link8.STL" material="camera_black" class="visual" />
                    </body>
                    <body name="link10" pos="-0.009 -0.04 0.083" quat="1.0 0.0 0.0 0.0">
                      <inertial pos="0.009 0.0087669 0.013992" quat="1.0 0.0 0.0 0.0" mass="0.0024292" diaginertia="5.7398e-07 5.1061e-07 2.6747e-07" />
                      <joint name="gripper_joint4" type="hinge" range="-0.82 0" axis="-1 0 0" armature="0.001" damping="0.05"/>
                      <!-- <geom name="link10_collision" pos="0 0 0" quat="1.0 0.0 0.0 0.0" type="mesh" mesh="link10.STL" class="collision" /> -->
                      <geom name="link10_visual" pos="0 0 0" quat="1.0 0.0 0.0 0.0" type="mesh" mesh="link10.STL" material="camera_black" class="visual" />
                      <body name="link12" pos="0.003 0.0223 0.035591" quat="1.0 0.0 0.0 0.0">
                        <inertial pos="0.006 0.011864 0.011367" quat="1.0 0.0 0.0 0.0" mass="0.0045068" diaginertia="5.3203e-07 5.1288e-07 2.009e-07" />
                        <joint name="gripper_joint6" type="hinge" range="0 0.82" axis="-1 0 0" />
                        <!-- <geom name="link12_collision" pos="0 0 0" quat="1.0 0.0 0.0 0.0" type="mesh" mesh="link12.STL" class="collision" /> -->
                        <geom name="link12_visual" pos="0 0 0" quat="1.0 0.0 0.0 0.0" type="mesh" mesh="link12.STL" material="camera_black" class="visual" />
                      </body>
                    </body>
                    <body name="link9" pos="-0.009 -0.03 0.085" quat="1.0 0.0 0.0 0.0">
                      <inertial pos="0.009 0.0087435 0.013955" quat="1.0 0.0 0.0 0.0" mass="0.0038971" diaginertia="6.2305e-07 5.6941e-07 3.0871e-07" />
                      <joint name="gripper_joint3" type="hinge" range="-0.82 0" axis="-1 0 0" />
                      <!-- <geom name="link9_collision" pos="0 0 0" quat="1.0 0.0 0.0 0.0" type="mesh" mesh="link9.STL" class="collision" /> -->
                      <geom name="link9_visual" pos="0 0 0" quat="1.0 0.0 0.0 0.0" type="mesh" mesh="link9.STL" material="camera_black" class="visual" />
                    </body>
                  </body>
                  
                  <body name="gripper_left" pos="0 -0.002 0.13">
                    <joint name="gripper_left_joint" type="slide" range="0 0.0205" axis="0 -1 0" class="gripper"/>
                    <geom type="box" size=".008 .002 .0165" rgba="0 0 1 1" class="collision"/>
                  </body>
                  <body name="gripper_right" pos="0 0.002 0.13">
                    <joint name="gripper_right_joint" type="slide" range="0 0.0205" axis="0 1 0" class="gripper"/>
                    <geom type="box" size=".008 .002 .0165" rgba="0 0 1 1" class="collision"/>
                  </body>

                  <body name="camera_link" pos="0.095 -0.003 0" quat="0.5003981633553667 -0.49999984146591736 -0.49960183664463337 0.49999984146591736">
                    <inertial pos="0.0016556 -0.01252 1.2156E-05" quat="1.0 0.0 0.0 0.0" mass="0.049778" diaginertia="4.8577e-06 3.075e-05 3.0901e-05" />
                    <geom name="camera_link_collision" pos="0 0 0" quat="1.0 0.0 0.0 0.0" type="mesh" mesh="camera_link.STL" class="collision" />
                    <geom name="camera_link_visual" pos="0 0 0" quat="1.0 0.0 0.0 0.0" type="mesh" mesh="camera_link.STL" material="camera_white" class="visual" />
                  </body>
                </body>
              </body>
            </body>
          </body>
        </body>
      </body>
    </body>
  </body>

</mujocoinclude>