<mujoco model="close_laptop">
  <include file="../object/kiwi_dependencies.xml"/>
  <compiler angle="radian" meshdir="../../meshes/" texturedir="../../meshes/"/>
  <worldbody>
    <site name="manipulator_locate" pos="0.3 0.92 0.71" euler="0 0 3.1416"/>
    <body name="lp1" pos="-0.025 0.925 0.7075" euler="0 0 3.1416">
      <body name="laptop_1" pos="0.01 0 0"/>
      <inertial pos="0 0 0" mass="0.35" diaginertia="0.0002 0.0002 0.0002"/>
      <geom size="0.12 0.166 0.0075" pos="0 0 0" type="box" rgba="0.1 .1 .1 1"/>
      <site name="laptop_bottom_site" pos="-0.12 0 0" euler="0 0 3.1416" size="0.001" type="sphere"/>
      <body name="lp2" pos="0.12 0 0.0075">
        <body name="laptop_2" pos="-0.00 0 0.005"/>
        <joint name="laptop_joint" axis="0 1 0" range="0 3.14" damping="0.002" frictionloss="1"/>
        <inertial pos="0 0 0" mass="0.005" diaginertia="0.000002 0.000002 0.000002"/>
        <geom size="0.12 0.166 0.005" pos="-0.12 0 0.0025" type="box" density="10" rgba="0.1 .1 .1 1"/>
        <site name="laptop_cam_site" pos="-0.24 0 0" euler="0 0 3.1416" size="0.001" type="sphere"/>
      </body>
    </body>
  </worldbody>
  <contact>
    <exclude body1="lp1" body2="lp2"/>
  </contact>
  <include file="../scene/qz_lab3.xml"/>
</mujoco>
